Workbook

Sheet Gelir Tablosu
A1: TMT A.O. — Konsolide Gelir Tablosu (TL)
A2: 1 Ocak - 31 Aralık | Bağımsız Denetimden Geçmiş
A3: Tutarlar Milyon TL olarak gösterilmiştir (aksi belirtilmedikçe)
A5: Kalem | B5: Dipnot | C5: 2024 (Mn TL) | D5: 2025 (Mn TL) | E5: Δ (Mn TL) | F5: % Değişim
A6: KÂR VEYA ZARAR KISMI
A7: Hasılat | B7: 26 | C7: 745430 | D7: 955472 | E7: =D7-C7 -> 210042 | F7: =IFERROR((D7-C7)/ABS(C7),"") -> 0.28177294
A8: Satışların Maliyeti (-) | B8: 27 | C8: -602522 | D8: -799912 | E8: =D8-C8 -> -197390 | F8: =IFERROR((D8-C8)/ABS(C8),"") -> -0.32760629
A9: BRÜT KÂR | C9: =C7+C8 -> 142908 | D9: =D7+D8 -> 155560 | E9: =D9-C9 -> 12652 | F9: =IFERROR((D9-C9)/ABS(C9),"") -> 0.088532482
A10: Genel Yönetim Giderleri (-) | B10: 28 | C10: -18675 | D10: -20774 | E10: =D10-C10 -> -2099 | F10: =IFERROR((D10-C10)/ABS(C10),"") -> -0.11239625
A11: Pazarlama Giderleri (-) | B11: 28 | C11: -60283 | D11: -71251 | E11: =D11-C11 -> -10968 | F11: =IFERROR((D11-C11)/ABS(C11),"") -> -0.18194184
A12: Esas Faaliyetlerden Diğer Gelirler | B12: 29 | C12: 20286 | D12: 30134 | E12: =D12-C12 -> 9848 | F12: =IFERROR((D12-C12)/ABS(C12),"") -> 0.48545795
A13: Esas Faaliyetlerden Diğer Giderler (-) | B13: 29 | C13: -3843 | D13: -3540 | E13: =D13-C13 -> 303 | F13: =IFERROR((D13-C13)/ABS(C13),"") -> 0.078844653
A14: ESAS FAALİYET KÂRI | C14: =C9+C10+C11+C12+C13 -> 80393 | D14: =D9+D10+D11+D12+D13 -> 90129 | E14: =D14-C14 -> 9736 | F14: =IFERROR((D14-C14)/ABS(C14),"") -> 0.12110507
A15: Yatırım Faaliyetlerinden Gelirler | B15: 30 | C15: 55375 | D15: 57072 | E15: =D15-C15 -> 1697 | F15: =IFERROR((D15-C15)/ABS(C15),"") -> 0.030645598
A16: Yatırım Faaliyetlerinden Giderler (-) | B16: 30 | C16: -2535 | D16: -2639 | E16: =D16-C16 -> -104 | F16: =IFERROR((D16-C16)/ABS(C16),"") -> -0.041025641
A17: Özkaynak Yöntemiyle Değerlenen Yatırımların Kârlarından Paylar | B17: 3 | C17: 5919 | D17: 4596 | E17: =D17-C17 -> -1323 | F17: =IFERROR((D17-C17)/ABS(C17),"") -> -0.22351749
A18: FİNANSMAN GELİRİ ÖNCESİ FAALİYET KÂRI | C18: =C14+C15+C16+C17 -> 139152 | D18: =D14+D15+D16+D17 -> 149158 | E18: =D18-C18 -> 10006 | F18: =IFERROR((D18-C18)/ABS(C18),"") -> 0.071906979
A19: Finansman Gelirleri | B19: 31 | C19: 32526 | D19: 30150 | E19: =D19-C19 -> -2376 | F19: =IFERROR((D19-C19)/ABS(C19),"") -> -0.073049253
A20: Finansman Giderleri (-) | B20: 31 | C20: -50335 | D20: -41809 | E20: =D20-C20 -> 8526 | F20: =IFERROR((D20-C20)/ABS(C20),"") -> 0.16938512
A21: Net Parasal Pozisyon Kazançları | B21: 32 | C21: 78 | D21: 79 | E21: =D21-C21 -> 1 | F21: =IFERROR((D21-C21)/ABS(C21),"") -> 0.012820513
A22: SÜRDÜRÜLEN FAALİYETLER VERGİ ÖNCESİ KÂRI | C22: =C18+C19+C20+C21 -> 121421 | D22: =D18+D19+D20+D21 -> 137578 | E22: =D22-C22 -> 16157 | F22: =IFERROR((D22-C22)/ABS(C22),"") -> 0.13306594
A23: Sürdürülen Faaliyetler Vergi Geliri/(Gideri) | C23: -8064 | D23: -19461 | E23: =D23-C23 -> -11397 | F23: =IFERROR((D23-C23)/ABS(C23),"") -> -1.4133185
A24: Dönem Vergi Gideri | B24: 33 | C24: -13345 | D24: -11524 | E24: =D24-C24 -> 1821 | F24: =IFERROR((D24-C24)/ABS(C24),"") -> 0.1364556
A25: Ertelenmiş Vergi (Gideri)/Geliri | B25: 33 | C25: 5281 | D25: -7937 | E25: =D25-C25 -> -13218 | F25: =IFERROR((D25-C25)/ABS(C25),"") -> -2.5029351
A26: SÜRDÜRÜLEN FAALİYETLER DÖNEM KÂRI | C26: =C22+C23 -> 113357 | D26: =D22+D23 -> 118117 | E26: =D26-C26 -> 4760 | F26: =IFERROR((D26-C26)/ABS(C26),"") -> 0.041991231
A28: DÖNEM KÂRININ DAĞILIMI
A29: Kontrol Gücü Olmayan Paylar | C29: -21 | D29: -91 | E29: =D29-C29 -> -70 | F29: =IFERROR((D29-C29)/ABS(C29),"") -> -3.3333333
A30: Ana Ortaklık Payları | C30: 113378 | D30: 118208 | E30: =D30-C30 -> 4830 | F30: =IFERROR((D30-C30)/ABS(C30),"") -> 0.042600857
A32: FAVÖK HESABI (Memorandum)
A33: Amortisman ve İtfa Gideri (Nakit Akıştan) | C33: 72306 | D33: 94682 | E33: =D33-C33 -> 22376 | F33: =IFERROR((D33-C33)/ABS(C33),"") -> 0.30946256
A34: FAVÖK (Esas Faal. Kârı + Amortisman) | C34: =C14+C33 -> 152699 | D34: =D14+D33 -> 184811 | E34: =D34-C34 -> 32112 | F34: =IFERROR((D34-C34)/ABS(C34),"") -> 0.21029607
A36: Faiz Gideri (Net — Nakit Akıştan) | C36: 21107 | D36: 21461 | E36: =D36-C36 -> 354 | F36: =IFERROR((D36-C36)/ABS(C36),"") -> 0.016771687
A38: Kaynak: THY 31.12.2025 Konsolide Kâr veya Zarar Tablosu (Bağımsız Denetimden Geçmiş)
A39: FAVÖK hesabı için amortisman ve faiz gideri Nakit Akış Tablosu'ndaki düzeltme kalemlerinden alınmıştır.

Sheet Nakit Akış
A1: TMT A.O. — Konsolide Nakit Akış Tablosu (TL)
A2: 1 Ocak - 31 Aralık
A3: Tutarlar Milyon TL olarak gösterilmiştir (aksi belirtilmedikçe)
A5: Kalem | C5: 2024 (Mn TL) | D5: 2025 (Mn TL) | E5: Δ (Mn TL) | F5: % Değişim
A6: A. İŞLETME FAALİYETLERİNDEN NAKİT AKIŞLARI
A7: Net Dönem Kârı | C7: =+'[1]THY Konsolide Nakit Akış Tablos'!$C$2 -> 113357 | D7: =+'[1]THY Konsolide Nakit Akış Tablos'!$B$2 -> 118117 | E7: =D7-C7 -> 4760 | F7: =IFERROR((D7-C7)/ABS(C7),"") -> 0.041991231
A8: Amortisman ve İtfa Düzeltmesi | C8: =+'[1]THY Konsolide Nakit Akış Tablos'!$C$4 -> 72306 | D8: =+'[1]THY Konsolide Nakit Akış Tablos'!$B$4 -> 94682 | E8: =D8-C8 -> 22376 | F8: =IFERROR((D8-C8)/ABS(C8),"") -> 0.30946256
A9: Çalışan Faydaları Karşılıkları | C9: =+'[1]THY Konsolide Nakit Akış Tablos'!$C$5 -> 3394 | D9: =+'[1]THY Konsolide Nakit Akış Tablos'!$B$5 -> 3246 | E9: =D9-C9 -> -148 | F9: =IFERROR((D9-C9)/ABS(C9),"") -> -0.043606364
A10: Diğer Karşılıklar | C10: =+'[1]THY Konsolide Nakit Akış Tablos'!$C$6 -> 304 | D10: =+'[1]THY Konsolide Nakit Akış Tablos'!$B$6 -> 3780 | E10: =D10-C10 -> 3476 | F10: =IFERROR((D10-C10)/ABS(C10),"") -> 11.434211
A11: =+'[1]THY Konsolide Nakit Akış Tablos'!$A$7 -> Muhtemel Riskler için Ayrılan Karşılıklar ile İlgili Düzeltmeler | C11: =+'[1]THY Konsolide Nakit Akış Tablos'!$C$7 -> -8 | D11: =+'[1]THY Konsolide Nakit Akış Tablos'!$B$7 -> 579
A12: Faiz Gelirleri (Düzeltme) | C12: =+'[1]THY Konsolide Nakit Akış Tablos'!$C$8 -> -53453 | D12: =+'[1]THY Konsolide Nakit Akış Tablos'!$B$8 -> -51849 | E12: =D12-C12 -> 1604 | F12: =IFERROR((D12-C12)/ABS(C12),"") -> 0.03000767
A13: Faiz Giderleri (Düzeltme) | C13: =+'[1]THY Konsolide Nakit Akış Tablos'!$C$9 -> 21107 | D13: =+'[1]THY Konsolide Nakit Akış Tablos'!$B$9 -> 21461 | E13: =D13-C13 -> 354 | F13: =IFERROR((D13-C13)/ABS(C13),"") -> 0.016771687
A14: Yabancı Para Çevrim Farkları (Gerçekleşmemiş) | C14: =+'[1]THY Konsolide Nakit Akış Tablos'!$C$10 -> -15079 | D14: =+'[1]THY Konsolide Nakit Akış Tablos'!$B$10 -> 11038 | E14: =D14-C14 -> 26117 | F14: =IFERROR((D14-C14)/ABS(C14),"") -> 1.7320114
A15: Türev Araç Değer Düzeltmesi | C15: =+'[1]THY Konsolide Nakit Akış Tablos'!$C$11 -> 7612 | D15: =+'[1]THY Konsolide Nakit Akış Tablos'!$B$11 -> -592 | E15: =D15-C15 -> -8204 | F15: =IFERROR((D15-C15)/ABS(C15),"") -> -1.0777719
A16: =+'[1]THY Konsolide Nakit Akış Tablos'!$A$12 -> Gerçeğe Uygun Değer Kayıpları ile İlgili Düzeltmeler | C16: =+'[1]THY Konsolide Nakit Akış Tablos'!$C$12 -> 2575 | D16: =+'[1]THY Konsolide Nakit Akış Tablos'!$B$12 -> #REF!
A17: =+'[1]THY Konsolide Nakit Akış Tablos'!$A$13 -> İştiraklerin Dağıtılmamış Karları İle İlgili Düzeltmeler | C17: =+'[1]THY Konsolide Nakit Akış Tablos'!$C$13 -> -5919 | D17: =+'[1]THY Konsolide Nakit Akış Tablos'!$B$13 -> -4596
A18: Vergi Gideri Düzeltmesi | C18: =+'[1]THY Konsolide Nakit Akış Tablos'!$C$14 -> 8064 | D18: =+'[1]THY Konsolide Nakit Akış Tablos'!$B$14 -> 19461 | E18: =D18-C18 -> 11397 | F18: =IFERROR((D18-C18)/ABS(C18),"") -> 1.4133185
A19: Diğer Düzeltmeler (toplam) | C19: =+'[1]THY Konsolide Nakit Akış Tablos'!$C$15+'[1]THY Konsolide Nakit Akış Tablos'!$C$17+'[1]THY Konsolide Nakit Akış Tablos'!$C$16 -> -5242 | D19: =+'[1]THY Konsolide Nakit Akış Tablos'!$B$15+'[1]THY Konsolide Nakit Akış Tablos'!$B$17+'[1]THY Konsolide Nakit Akış Tablos'!$B$16 -> #REF! | E19: =D19-C19 -> #REF! | F19: =IFERROR((D19-C19)/ABS(C19),"")
A20: Ara Toplam (Düzeltmeler Sonrası) | C20: =SUM(C7:C19) -> 149018 | D20: =SUM(D7:D19) -> #REF! | E20: =D20-C20 -> #REF! | F20: =IFERROR((D20-C20)/ABS(C20),"")
A21: İşletme Sermayesi Değişimleri (net) | C21: =SUM('[1]THY Konsolide Nakit Akış Tablos'!$C$20:$C$32) -> 9319 | D21: =SUM('[1]THY Konsolide Nakit Akış Tablos'!$B$20:$B$32) -> -7523 | E21: =D21-C21 -> -16842 | F21: =IFERROR((D21-C21)/ABS(C21),"") -> -1.8072755
A22: Ödemeler (Vergi + Çalışan Faydaları) | C22: =SUM('[1]THY Konsolide Nakit Akış Tablos'!$C$35:$C$36) -> -1863 | D22: =SUM('[1]THY Konsolide Nakit Akış Tablos'!$B$35:$B$36) -> -6674 | E22: =D22-C22 -> -4811 | F22: =IFERROR((D22-C22)/ABS(C22),"") -> -2.582394
A23: İşletme Faaliyetlerinden Net Nakit | C23: =SUM(C20:C22) -> 156474 | D23: =SUM(D20:D22) -> #REF! | E23: =D23-C23 -> #REF! | F23: =IFERROR((D23-C23)/ABS(C23),"")
A25: B. YATIRIM FAALİYETLERİNDEN NAKİT AKIŞLARI
A26: Maddi Duran Varlık Alımı (CapEx — brüt çıkış) | C26: =+'[1]THY Konsolide Nakit Akış Tablos'!$C$40 -> -43963 | D26: =+'[1]THY Konsolide Nakit Akış Tablos'!$B$40 -> -80117 | E26: =D26-C26 -> -36154 | F26: =IFERROR((D26-C26)/ABS(C26),"") -> -0.82237336
A27: Maddi Duran Varlık Satışı (giriş) | C27: =+'[1]THY Konsolide Nakit Akış Tablos'!$C$39 -> 464 | D27: =+'[1]THY Konsolide Nakit Akış Tablos'!$B$39 -> 3301 | E27: =D27-C27 -> 2837 | F27: =IFERROR((D27-C27)/ABS(C27),"") -> 6.1142241
A28: Diğer Yatırım Kalemleri (net) | C28: =+'[1]THY Konsolide Nakit Akış Tablos'!$C$41+'[1]THY Konsolide Nakit Akış Tablos'!$C$42+'[1]THY Konsolide Nakit Akış Tablos'!$C$43+'[1]THY Konsolide Nakit Akış Tablos'!$C$44+'[1]THY Konsolide Nakit Akış Tablos'!$C$45 -> #REF! | D28: =+'[1]THY Konsolide Nakit Akış Tablos'!$B$41+'[1]THY Konsolide Nakit Akış Tablos'!$B$42+'[1]THY Konsolide Nakit Akış Tablos'!$B$43+'[1]THY Konsolide Nakit Akış Tablos'!$B$44+'[1]THY Konsolide Nakit Akış Tablos'!$B$45 -> -67853 | E28: =D28-C28 -> #REF! | F28: =IFERROR((D28-C28)/ABS(C28),"")
A29: Yatırım Faaliyetlerinden Net Nakit | C29: =SUM(C26:C28) -> #REF! | D29: =SUM(D26:D28) -> -144669 | E29: =D29-C29 -> #REF! | F29: =IFERROR((D29-C29)/ABS(C29),"")
A31: C. FİNANSMAN FAALİYETLERİNDEN NAKİT AKIŞLARI
A32: Yeni Krediler (giriş) | C32: =+'[1]THY Konsolide Nakit Akış Tablos'!$C$50 -> 90716 | D32: =+'[1]THY Konsolide Nakit Akış Tablos'!$B$50 -> 183574 | E32: =D32-C32 -> 92858 | F32: =IFERROR((D32-C32)/ABS(C32),"") -> 1.0236122
A33: Kredi Geri Ödemeleri (-) | C33: =+'[1]THY Konsolide Nakit Akış Tablos'!$C$51 -> -102308 | D33: =+'[1]THY Konsolide Nakit Akış Tablos'!$B$51 -> -147173 | E33: =D33-C33 -> -44865 | F33: =IFERROR((D33-C33)/ABS(C33),"") -> -0.43852876
A34: Kira Borç Ödemeleri (-) | C34: =+'[1]THY Konsolide Nakit Akış Tablos'!$C$52 -> -61522 | D34: =+'[1]THY Konsolide Nakit Akış Tablos'!$B$52 -> -82311 | E34: =D34-C34 -> -20789 | F34: =IFERROR((D34-C34)/ABS(C34),"") -> -0.33791164
A35: Temettü Ödemeleri (-) | C35: =+'[1]THY Konsolide Nakit Akış Tablos'!$C$53 -> #REF! | D35: =+'[1]THY Konsolide Nakit Akış Tablos'!$B$53 -> -8951 | E35: =D35-C35 -> #REF! | F35: =IFERROR((D35-C35)/ABS(C35),"")
A36: Ödenen Faiz (-) | C36: =+'[1]THY Konsolide Nakit Akış Tablos'!$C$54 -> -12543 | D36: =+'[1]THY Konsolide Nakit Akış Tablos'!$B$54 -> -12129 | E36: =D36-C36 -> 414 | F36: =IFERROR((D36-C36)/ABS(C36),"") -> 0.033006458
A37: Alınan Faiz (+) | C37: =+'[1]THY Konsolide Nakit Akış Tablos'!$C$55 -> 10495 | D37: =+'[1]THY Konsolide Nakit Akış Tablos'!$B$55 -> 17985 | E37: =D37-C37 -> 7490 | F37: =IFERROR((D37-C37)/ABS(C37),"") -> 0.71367318
A38: Diğer Finansman Kalemleri (net) | C38: =+'[1]THY Konsolide Nakit Akış Tablos'!$C$56+'[1]THY Konsolide Nakit Akış Tablos'!$C$48+'[1]THY Konsolide Nakit Akış Tablos'!$C$49 -> #REF! | D38: =+'[1]THY Konsolide Nakit Akış Tablos'!$B$56+'[1]THY Konsolide Nakit Akış Tablos'!$B$48+'[1]THY Konsolide Nakit Akış Tablos'!$B$49 -> -229 | E38: =D38-C38 -> #REF! | F38: =IFERROR((D38-C38)/ABS(C38),"")
A39: Finansman Faaliyetlerinde Kullanılan Net Nakit | C39: =SUM(C32:C38) -> #REF! | D39: =SUM(D32:D38) -> -49234 | E39: =D39-C39 -> #REF! | F39: =IFERROR((D39-C39)/ABS(C39),"")
A41: Yabancı Para Çevrim Etkisi | C41: =+'[1]THY Konsolide Nakit Akış Tablos'!$C$59 -> -20894 | D41: =+'[1]THY Konsolide Nakit Akış Tablos'!$B$59 -> 1109 | E41: =D41-C41 -> 22003 | F41: =IFERROR((D41-C41)/ABS(C41),"") -> 1.0530774
A42: Nakit ve Nakit Benzerlerindeki Net Değişim | C42: =+C41+C39+C29+C23 -> #REF! | D42: =+D41+D39+D29+D23 -> #REF! | E42: =D42-C42 -> #REF! | F42: =IFERROR((D42-C42)/ABS(C42),"")
A43: Dönem Başı Nakit | C43: =+'[1]THY Konsolide Nakit Akış Tablos'!$C$61 -> 19941 | D43: =+'[1]THY Konsolide Nakit Akış Tablos'!$B$61 -> 90164 | E43: =D43-C43 -> 70223 | F43: =IFERROR((D43-C43)/ABS(C43),"") -> 3.5215385
A44: DÖNEM SONU NAKİT | C44: =+C43+C42 -> #REF! | D44: =+D43+D42 -> #REF! | E44: =D44-C44 -> #REF! | F44: =IFERROR((D44-C44)/ABS(C44),"")
...

Sheet Varlıklar
A1: TMT A.O. ve BAĞLI ORTAKLIKLARI
A2: Konsolide Finansal Durum Tablosu — Varlıklar
A3: Tutarlar Milyon TL olarak gösterilmiştir (aksi belirtilmedikçe)
A5: Kalem | B5: Dipnot | C5: 31 Aralık 2024 | D5: 31 Aralık 2025 | E5: Δ (Mn TL) | F5: % Değişim | G5: % Pay 2024 | H5: % Pay 2025 | I5: Δ pp
A6: DÖNEN VARLIKLAR
A7: Nakit ve Nakit Benzerleri | B7: 5 | C7: 95992 | D7: 86035 | E7: =D7-C7 -> -9957 | F7: =IF(C7=0,"",(D7-C7)/ABS(C7)) -> -0.10372739 | G7: =IFERROR(C7/C$38,"") -> 0.068585016 | H7: =IFERROR(D7/D$38,"") -> 0.043087625 | I7: =IFERROR((D7/D$38)-(C7/C$38),"") -> -0.025497391
A8: Finansal Yatırımlar | B8: 6 | C8: 118030 | D8: 182732 | E8: =D8-C8 -> 64702 | F8: =IF(C8=0,"",(D8-C8)/ABS(C8)) -> 0.54818267 | G8: =IFERROR(C8/C$38,"") -> 0.084330876 | H8: =IFERROR(D8/D$38,"") -> 0.091514941 | I8: =IFERROR((D8/D$38)-(C8/C$38),"") -> 0.0071840646
A9: Ticari Alacaklar
A10: İlişkili Taraflardan Ticari Alacaklar | B10: 9 | C10: 1506 | D10: 1527 | E10: =D10-C10 -> 21 | F10: =IF(C10=0,"",(D10-C10)/ABS(C10)) -> 0.013944223 | G10: =IFERROR(C10/C$38,"") -> 0.0010760171 | H10: =IFERROR(D10/D$38,"") -> 0.00076474462 | I10: =IFERROR((D10/D$38)-(C10/C$38),"") -> -0.00031127249
A11: İlişkili Olmayan Taraflardan Ticari Alacaklar | B11: 10 | C11: 30402 | D11: 44264 | E11: =D11-C11 -> 13862 | F11: =IF(C11=0,"",(D11-C11)/ABS(C11)) -> 0.45595684 | G11: =IFERROR(C11/C$38,"") -> 0.021721827 | H11: =IFERROR(D11/D$38,"") -> 0.022168079 | I11: =IFERROR((D11/D$38)-(C11/C$38),"") -> 0.00044625112
A12: Diğer Alacaklar
A13: İlişkili Taraflardan Diğer Alacaklar | B13: 9 | C13: 318 | D13: 0 | E13: =D13-C13 -> -318 | F13: =IF(C13=0,"",(D13-C13)/ABS(C13)) -> -1 | G13: =IFERROR(C13/C$38,"") -> 0.0002272068 | H13: =IFERROR(D13/D$38,"") -> 0 | I13: =IFERROR((D13/D$38)-(C13/C$38),"") -> -0.0002272068
A14: İlişkili Olmayan Taraflardan Diğer Alacaklar | B14: 12 | C14: 47947 | D14: 39367 | E14: =D14-C14 -> -8580 | F14: =IF(C14=0,"",(D14-C14)/ABS(C14)) -> -0.17894759 | G14: =IFERROR(C14/C$38,"") -> 0.034257498 | H14: =IFERROR(D14/D$38,"") -> 0.019715587 | I14: =IFERROR((D14/D$38)-(C14/C$38),"") -> -0.014541911
A15: Türev Araçlar | B15: 35 | C15: 4213 | D15: 10583 | E15: =D15-C15 -> 6370 | F15: =IF(C15=0,"",(D15-C15)/ABS(C15)) -> 1.5119867 | G15: =IFERROR(C15/C$38,"") -> 0.0030101329 | H15: =IFERROR(D15/D$38,"") -> 0.005300126 | I15: =IFERROR((D15/D$38)-(C15/C$38),"") -> 0.0022899931
A16: Stoklar | B16: 13 | C16: 23661 | D16: 41472 | E16: =D16-C16 -> 17811 | F16: =IF(C16=0,"",(D16-C16)/ABS(C16)) -> 0.7527577 | G16: =IFERROR(C16/C$38,"") -> 0.016905472 | H16: =IFERROR(D16/D$38,"") -> 0.020769803 | I16: =IFERROR((D16/D$38)-(C16/C$38),"") -> 0.0038643309
A17: Peşin Ödenmiş Giderler | B17: 14 | C17: 10641 | D17: 18054 | E17: =D17-C17 -> 7413 | F17: =IF(C17=0,"",(D17-C17)/ABS(C17)) -> 0.69664505 | G17: =IFERROR(C17/C$38,"") -> 0.0076028539 | H17: =IFERROR(D17/D$38,"") -> 0.0090417154 | I17: =IFERROR((D17/D$38)-(C17/C$38),"") -> 0.0014388614
A18: Cari Dönem Vergisiyle İlgili Varlıklar | B18: 33 | C18: 1014 | D18: 0 | E18: =D18-C18 -> -1014 | F18: =IF(C18=0,"",(D18-C18)/ABS(C18)) -> -1 | G18: =IFERROR(C18/C$38,"") -> 0.00072448961 | H18: =IFERROR(D18/D$38,"") -> 0 | I18: =IFERROR((D18/D$38)-(C18/C$38),"") -> -0.00072448961
A19: Diğer Dönen Varlıklar | B19: 24 | C19: 8186 | D19: 12378 | E19: =D19-C19 -> 4192 | F19: =IF(C19=0,"",(D19-C19)/ABS(C19)) -> 0.51209382 | G19: =IFERROR(C19/C$38,"") -> 0.0058487889 | H19: =IFERROR(D19/D$38,"") -> 0.006199089 | I19: =IFERROR((D19/D$38)-(C19/C$38),"") -> 0.00035030014
A20: TOPLAM DÖNEN VARLIKLAR | C20: =SUM(C7:C19) -> 341910 | D20: =SUM(D7:D19) -> 436412 | E20: =D20-C20 -> 94502 | F20: =IF(C20=0,"",(D20-C20)/ABS(C20)) -> 0.27639437 | G20: =IFERROR(C20/C$38,"") -> 0.24429018 | H20: =IFERROR(D20/D$38,"") -> 0.21856171 | I20: =IFERROR((D20/D$38)-(C20/C$38),"") -> -0.02572847
A22: DURAN VARLIKLAR
A23: Finansal Yatırımlar | B23: 6 | C23: 39253 | D23: 114960 | E23: =D23-C23 -> 75707 | F23: =IF(C23=0,"",(D23-C23)/ABS(C23)) -> 1.9286933 | G23: =IFERROR(C23/C$38,"") -> 0.02804575 | H23: =IFERROR(D23/D$38,"") -> 0.057573701 | I23: =IFERROR((D23/D$38)-(C23/C$38),"") -> 0.029527951
A24: Diğer Alacaklar
A25: İlişkili Taraflardan Diğer Alacaklar | B25: 9 | C25: 423 | D25: 2290 | E25: =D25-C25 -> 1867 | F25: =IF(C25=0,"",(D25-C25)/ABS(C25)) -> 4.4137116 | G25: =IFERROR(C25/C$38,"") -> 0.00030222791 | H25: =IFERROR(D25/D$38,"") -> 0.0011468665 | I25: =IFERROR((D25/D$38)-(C25/C$38),"") -> 0.00084463861
A26: İlişkili Olmayan Taraflardan Diğer Alacaklar | B26: 12 | C26: 44178 | D26: 84601 | E26: =D26-C26 -> 40423 | F26: =IF(C26=0,"",(D26-C26)/ABS(C26)) -> 0.91500294 | G26: =IFERROR(C26/C$38,"") -> 0.031564597 | H26: =IFERROR(D26/D$38,"") -> 0.042369456 | I26: =IFERROR((D26/D$38)-(C26/C$38),"") -> 0.010804859
A27: Özkaynak Yöntemiyle Değerlenen Yatırımlar | B27: 3 | C27: 22707 | D27: 32672 | E27: =D27-C27 -> 9965 | F27: =IF(C27=0,"",(D27-C27)/ABS(C27)) -> 0.43885146 | G27: =IFERROR(C27/C$38,"") -> 0.016223852 | H27: =IFERROR(D27/D$38,"") -> 0.01636263 | I27: =IFERROR((D27/D$38)-(C27/C$38),"") -> 0.00013877861
A28: Yatırım Amaçlı Gayrimenkuller | B28: 15 | C28: 1523 | D28: 1853 | E28: =D28-C28 -> 330 | F28: =IF(C28=0,"",(D28-C28)/ABS(C28)) -> 0.21667761 | G28: =IFERROR(C28/C$38,"") -> 0.0010881634 | H28: =IFERROR(D28/D$38,"") -> 0.00092801034 | I28: =IFERROR((D28/D$38)-(C28/C$38),"") -> -0.00016015305
A29: Maddi Duran Varlıklar | B29: 16 | C29: 248909 | D29: 362618 | E29: =D29-C29 -> 113709 | F29: =IF(C29=0,"",(D29-C29)/ABS(C29)) -> 0.4568296 | G29: =IFERROR(C29/C$38,"") -> 0.17784219 | H29: =IFERROR(D29/D$38,"") -> 0.18160456 | I29: =IFERROR((D29/D$38)-(C29/C$38),"") -> 0.0037623687
A30: Kullanım Hakkı Varlıkları | B30: 16 | C30: 621795 | D30: 847758 | E30: =D30-C30 -> 225963 | F30: =IF(C30=0,"",(D30-C30)/ABS(C30)) -> 0.36340434 | G30: =IFERROR(C30/C$38,"") -> 0.44426431 | H30: =IFERROR(D30/D$38,"") -> 0.42456999 | I30: =IFERROR((D30/D$38)-(C30/C$38),"") -> -0.019694327
A31: Maddi Olmayan Duran Varlıklar
A32: Diğer Maddi Olmayan Duran Varlıklar | B32: 17 | C32: 3943 | D32: 7722 | E32: =D32-C32 -> 3779 | F32: =IF(C32=0,"",(D32-C32)/ABS(C32)) -> 0.9584073 | G32: =IFERROR(C32/C$38,"") -> 0.0028172214 | H32: =IFERROR(D32/D$38,"") -> 0.003867294 | I32: =IFERROR((D32/D$38)-(C32/C$38),"") -> 0.0010500726
A33: Şerefiye | C33: 943 | D33: 1145 | E33: =D33-C33 -> 202 | F33: =IF(C33=0,"",(D33-C33)/ABS(C33)) -> 0.21420997 | G33: =IFERROR(C33/C$38,"") -> 0.00067376104 | H33: =IFERROR(D33/D$38,"") -> 0.00057343326 | I33: =IFERROR((D33/D$38)-(C33/C$38),"") -> -0.00010032778
A34: Peşin Ödenmiş Giderler | B34: 14 | C34: 59824 | D34: 87002 | E34: =D34-C34 -> 27178 | F34: =IF(C34=0,"",(D34-C34)/ABS(C34)) -> 0.45429928 | G34: =IFERROR(C34/C$38,"") -> 0.042743458 | H34: =IFERROR(D34/D$38,"") -> 0.043571913 | I34: =IFERROR((D34/D$38)-(C34/C$38),"") -> 0.00082845549
A35: Ertelenmiş Vergi Varlığı | B35: 33 | C35: 14198 | D35: 17712 | E35: =D35-C35 -> 3514 | F35: =IF(C35=0,"",(D35-C35)/ABS(C35)) -> 0.24749965 | G35: =IFERROR(C35/C$38,"") -> 0.010144283 | H35: =IFERROR(D35/D$38,"") -> 0.0088704366 | I35: =IFERROR((D35/D$38)-(C35/C$38),"") -> -0.0012738468
A36: TOPLAM DURAN VARLIKLAR | C36: =SUM(C23:C35) -> 1057696 | D36: =SUM(D23:D35) -> 1560333 | E36: =D36-C36 -> 502637 | F36: =IF(C36=0,"",(D36-C36)/ABS(C36)) -> 0.47521878 | G36: =IFERROR(C36/C$38,"") -> 0.75570982 | H36: =IFERROR(D36/D$38,"") -> 0.78143829 | I36: =IFERROR((D36/D$38)-(C36/C$38),"") -> 0.02572847
A38: TOPLAM VARLIKLAR | C38: =C20+C36 -> 1399606 | D38: =D20+D36 -> 1996745 | E38: =D38-C38 -> 597139 | F38: =IF(C38=0,"",(D38-C38)/ABS(C38)) -> 0.42664793 | G38: =IFERROR(C38/C$38,"") -> 1 | H38: =IFERROR(D38/D$38,"") -> 1 | I38: =IFERROR((D38/D$38)-(C38/C$38),"") -> 0
A40: Kaynak: THY 31.12.2025 Konsolide Finansal Durum Tablosu (Bağımsız Denetimden Geçmiş)

Sheet Kaynaklar
A1: TMT A.O. ve BAĞLI ORTAKLIKLARI
A2: Konsolide Finansal Durum Tablosu — Kaynaklar (Yükümlülükler + Özkaynaklar)
A3: Tutarlar Milyon TL olarak gösterilmiştir (aksi belirtilmedikçe)
A5: Kalem | B5: Dipnot | C5: 31 Aralık 2024 | D5: 31 Aralık 2025 | E5: Δ (Mn TL) | F5: % Değişim | G5: % Pay 2024 | H5: % Pay 2025 | I5: Δ pp
A6: KISA VADELİ YÜKÜMLÜLÜKLER
A7: Kısa Vadeli Borçlanmalar
A8: İlişkili Olmayan Taraflardan KV Borçlanmalar - Banka Kredileri | B8: 7 | C8: 55536 | D8: 70069 | E8: =D8-C8 -> 14533 | F8: =IF(C8=0,"",(D8-C8)/ABS(C8)) -> 0.26168611 | G8: =IFERROR(C8/C$61,"") -> 0.039679738 | H8: =IFERROR(D8/D$61,"") -> 0.035091612 | I8: =IFERROR((D8/D$61)-(C8/C$61),"") -> -0.0045881268
A9: UV Borçlanmaların KV Kısımları
A10: İlişkili Taraflardan UV Borçlanmaların KV Kısımları - Banka Kredileri | B10: 7 | C10: 164 | D10: 0 | E10: =D10-C10 -> -164 | F10: =IF(C10=0,"",(D10-C10)/ABS(C10)) -> -1 | G10: =IFERROR(C10/C$61,"") -> 0.00011717583 | H10: =IFERROR(D10/D$61,"") -> 0 | I10: =IFERROR((D10/D$61)-(C10/C$61),"") -> -0.00011717583
A11: İlişkili Olmayan Taraflardan UV Borçlanmaların KV Kısımları - Banka Kredileri | B11: 7 | C11: 10139 | D11: 6215 | E11: =D11-C11 -> -3924 | F11: =IF(C11=0,"",(D11-C11)/ABS(C11)) -> -0.38702042 | G11: =IFERROR(C11/C$61,"") -> 0.0072441816 | H11: =IFERROR(D11/D$61,"") -> 0.0031125657 | I11: =IFERROR((D11/D$61)-(C11/C$61),"") -> -0.0041316159
A12: İlişkili Olmayan Taraflardan UV Borçlanmaların KV Kısımları - Kiralama İşlemlerinden Borçlanmalar | B12: 7-18 | C12: 64571 | D12: 86152 | E12: =D12-C12 -> 21581 | F12: =IF(C12=0,"",(D12-C12)/ABS(C12)) -> 0.33422124 | G12: =IFERROR(C12/C$61,"") -> 0.046135127 | H12: =IFERROR(D12/D$61,"") -> 0.04314622 | I12: =IFERROR((D12/D$61)-(C12/C$61),"") -> -0.0029889061
A13: Diğer Finansal Yükümlülükler | B13: 8 | C13: 0 | D13: 1 | E13: =D13-C13 -> 1 | F13: =IF(C13=0,"",(D13-C13)/ABS(C13)) | G13: =IFERROR(C13/C$61,"") -> 0 | H13: =IFERROR(D13/D$61,"") -> 5.0081508e-07 | I13: =IFERROR((D13/D$61)-(C13/C$61),"") -> 5.0081508e-07
A14: Ticari Borçlar
A15: İlişkili Taraflara Ticari Borçlar | B15: 9 | C15: 10342 | D15: 13251 | E15: =D15-C15 -> 2909 | F15: =IF(C15=0,"",(D15-C15)/ABS(C15)) -> 0.28128022 | G15: =IFERROR(C15/C$61,"") -> 0.0073892224 | H15: =IFERROR(D15/D$61,"") -> 0.0066363006 | I15: =IFERROR((D15/D$61)-(C15/C$61),"") -> -0.00075292182
A16: İlişkili Olmayan Taraflara Ticari Borçlar | B16: 10 | C16: 42450 | D16: 65389 | E16: =D16-C16 -> 22939 | F16: =IF(C16=0,"",(D16-C16)/ABS(C16)) -> 0.54037691 | G16: =IFERROR(C16/C$61,"") -> 0.030329964 | H16: =IFERROR(D16/D$61,"") -> 0.032747797 | I16: =IFERROR((D16/D$61)-(C16/C$61),"") -> 0.0024178327
A17: Çalışanlara Sağlanan Faydalar Kapsamında Borçlar | B17: 11 | C17: 18957 | D17: 20082 | E17: =D17-C17 -> 1125 | F17: =IF(C17=0,"",(D17-C17)/ABS(C17)) -> 0.059344833 | G17: =IFERROR(C17/C$61,"") -> 0.013544526 | H17: =IFERROR(D17/D$61,"") -> 0.010057368 | I17: =IFERROR((D17/D$61)-(C17/C$61),"") -> -0.0034871577
A18: Diğer Borçlar
A19: İlişkili Taraflara Diğer Borçlar | B19: 9 | C19: 23 | D19: 1321 | E19: =D19-C19 -> 1298 | F19: =IF(C19=0,"",(D19-C19)/ABS(C19)) -> 56.434783 | G19: =IFERROR(C19/C$61,"") -> 1.6433196e-05 | H19: =IFERROR(D19/D$61,"") -> 0.00066157672 | I19: =IFERROR((D19/D$61)-(C19/C$61),"") -> 0.00064514352
A20: İlişkili Olmayan Taraflara Diğer Borçlar | B20: 12 | C20: 11143 | D20: 10407 | E20: =D20-C20 -> -736 | F20: =IF(C20=0,"",(D20-C20)/ABS(C20)) -> -0.066050435 | G20: =IFERROR(C20/C$61,"") -> 0.0079615263 | H20: =IFERROR(D20/D$61,"") -> 0.0052119825 | I20: =IFERROR((D20/D$61)-(C20/C$61),"") -> -0.0027495438
A21: Türev Araçlar | B21: 35 | C21: 1301 | D21: 6359 | E21: =D21-C21 -> 5058 | F21: =IF(C21=0,"",(D21-C21)/ABS(C21)) -> 3.8877786 | G21: =IFERROR(C21/C$61,"") -> 0.00092954732 | H21: =IFERROR(D21/D$61,"") -> 0.0031846831 | I21: =IFERROR((D21/D$61)-(C21/C$61),"") -> 0.0022551358
A22: Ertelenmiş Gelirler | B22: 14 | C22: 104054 | D22: 151257 | E22: =D22-C22 -> 47203 | F22: =IF(C22=0,"",(D22-C22)/ABS(C22)) -> 0.45363946 | G22: =IFERROR(C22/C$61,"") -> 0.074345209 | H22: =IFERROR(D22/D$61,"") -> 0.075751786 | I22: =IFERROR((D22/D$61)-(C22/C$61),"") -> 0.0014065775
A23: Dönem Karı Vergi Yükümlülüğü | B23: 33 | C23: 0 | D23: 430 | E23: =D23-C23 -> 430 | F23: =IF(C23=0,"",(D23-C23)/ABS(C23)) | G23: =IFERROR(C23/C$61,"") -> 0 | H23: =IFERROR(D23/D$61,"") -> 0.00021535048 | I23: =IFERROR((D23/D$61)-(C23/C$61),"") -> 0.00021535048
A24: Kısa Vadeli Karşılıklar
A25: Çalışanlara Sağlanan Faydalara İlişkin KV Karşılıklar | B25: 20 | C25: 3571 | D25: 5603 | E25: =D25-C25 -> 2032 | F25: =IF(C25=0,"",(D25-C25)/ABS(C25)) -> 0.56902828 | G25: =IFERROR(C25/C$61,"") -> 0.0025514323 | H25: =IFERROR(D25/D$61,"") -> 0.0028060669 | I25: =IFERROR((D25/D$61)-(C25/C$61),"") -> 0.00025463454
A26: Diğer KV Karşılıklar | B26: 20 | C26: 478 | D26: 794 | E26: =D26-C26 -> 316 | F26: =IF(C26=0,"",(D26-C26)/ABS(C26)) -> 0.66108787 | G26: =IFERROR(C26/C$61,"") -> 0.00034152469 | H26: =IFERROR(D26/D$61,"") -> 0.00039764717 | I26: =IFERROR((D26/D$61)-(C26/C$61),"") -> 5.6122485e-05
A27: Diğer Kısa Vadeli Yükümlülükler | B27: 24 | C27: 16804 | D27: 4746 | E27: =D27-C27 -> -12058 | F27: =IF(C27=0,"",(D27-C27)/ABS(C27)) -> -0.71756725 | G27: =IFERROR(C27/C$61,"") -> 0.012006236 | H27: =IFERROR(D27/D$61,"") -> 0.0023768684 | I27: =IFERROR((D27/D$61)-(C27/C$61),"") -> -0.0096293677
A28: TOPLAM KISA VADELİ YÜKÜMLÜLÜKLER | C28: =SUM(C7:C27) -> 339533 | D28: =SUM(D7:D27) -> 442076 | E28: =D28-C28 -> 102543 | F28: =IF(C28=0,"",(D28-C28)/ABS(C28)) -> 0.30201188 | G28: =IFERROR(C28/C$61,"") -> 0.24259184 | H28: =IFERROR(D28/D$61,"") -> 0.22139833 | I28: =IFERROR((D28/D$61)-(C28/C$61),"") -> -0.021193518
A30: UZUN VADELİ YÜKÜMLÜLÜKLER
A31: Uzun Vadeli Borçlanmalar
A32: İlişkili Olmayan Taraflardan UV Borçlanmalar - Banka Kredileri | B32: 7 | C32: 1176 | D32: 48993 | E32: =D32-C32 -> 47817 | F32: =IF(C32=0,"",(D32-C32)/ABS(C32)) -> 40.660714 | G32: =IFERROR(C32/C$61,"") -> 0.00084023647 | H32: =IFERROR(D32/D$61,"") -> 0.024536433 | I32: =IFERROR((D32/D$61)-(C32/C$61),"") -> 0.023696197
A33: İlişkili Olmayan Taraflardan UV Borçlanmalar - Kiralama İşlemlerinden Borçlanmalar | B33: 7-18 | C33: 358353 | D33: 552824 | E33: =D33-C33 -> 194471 | F33: =IF(C33=0,"",(D33-C33)/ABS(C33)) -> 0.54267998 | G33: =IFERROR(C33/C$61,"") -> 0.25603849 | H33: =IFERROR(D33/D$61,"") -> 0.27686259 | I33: =IFERROR((D33/D$61)-(C33/C$61),"") -> 0.020824109
A34: Diğer Borçlar - İlişkili Olmayan Taraflara | B34: 12 | C34: 1115 | D34: 1235 | E34: =D34-C34 -> 120 | F34: =IF(C34=0,"",(D34-C34)/ABS(C34)) -> 0.10762332 | G34: =IFERROR(C34/C$61,"") -> 0.00079665277 | H34: =IFERROR(D34/D$61,"") -> 0.00061850662 | I34: =IFERROR((D34/D$61)-(C34/C$61),"") -> -0.00017814615
A35: Ertelenmiş Gelirler | B35: 14 | C35: 4629 | D35: 3240 | E35: =D35-C35 -> -1389 | F35: =IF(C35=0,"",(D35-C35)/ABS(C35)) -> -0.30006481 | G35: =IFERROR(C35/C$61,"") -> 0.0033073594 | H35: =IFERROR(D35/D$61,"") -> 0.0016226408 | I35: =IFERROR((D35/D$61)-(C35/C$61),"") -> -0.0016847185
A36: Uzun Vadeli Karşılıklar
A37: Çalışanlara Sağlanan Faydalara İlişkin UV Karşılıklar | B37: 22 | C37: 8725 | D37: 12110 | E37: =D37-C37 -> 3385 | F37: =IF(C37=0,"",(D37-C37)/ABS(C37)) -> 0.38796562 | G37: =IFERROR(C37/C$61,"") -> 0.0062338973 | H37: =IFERROR(D37/D$61,"") -> 0.0060648706 | I37: =IFERROR((D37/D$61)-(C37/C$61),"") -> -0.00016902668
A38: Diğer UV Karşılıklar | B38: 20 | C38: 3778 | D38: 8367 | E38: =D38-C38 -> 4589 | F38: =IF(C38=0,"",(D38-C38)/ABS(C38)) -> 1.2146638 | G38: =IFERROR(C38/C$61,"") -> 0.0026993311 | H38: =IFERROR(D38/D$61,"") -> 0.0041903197 | I38: =IFERROR((D38/D$61)-(C38/C$61),"") -> 0.0014909886
A39: Ertelenmiş Vergi Yükümlülüğü | B39: 33 | C39: 2285 | D39: 3116 | E39: =D39-C39 -> 831 | F39: =IF(C39=0,"",(D39-C39)/ABS(C39)) -> 0.36367615 | G39: =IFERROR(C39/C$61,"") -> 0.0016326023 | H39: =IFERROR(D39/D$61,"") -> 0.0015605398 | I39: =IFERROR((D39/D$61)-(C39/C$61),"") -> -7.206254e-05
A40: Diğer Uzun Vadeli Yükümlülükler | B40: 24 | C40: 0 | D40: 13528 | E40: =D40-C40 -> 13528 | F40: =IF(C40=0,"",(D40-C40)/ABS(C40)) | G40: =IFERROR(C40/C$61,"") -> 0 | H40: =IFERROR(D40/D$61,"") -> 0.0067750264 | I40: =IFERROR((D40/D$61)-(C40/C$61),"") -> 0.0067750264
A41: TOPLAM UZUN VADELİ YÜKÜMLÜLÜKLER | C41: =SUM(C31:C40) -> 380061 | D41: =SUM(D31:D40) -> 643413 | E41: =D41-C41 -> 263352 | F41: =IF(C41=0,"",(D41-C41)/ABS(C41)) -> 0.69292035 | G41: =IFERROR(C41/C$61,"") -> 0.27154856 | H41: =IFERROR(D41/D$61,"") -> 0.32223093 | I41: =IFERROR((D41/D$61)-(C41/C$61),"") -> 0.050682366
A43: ÖZKAYNAKLAR
...

Sheet Dikey Analiz
A1: TMT A.O. — Dikey Analiz (Common-Size Bilanço)
A2: Varlık tarafı: paylar Toplam Varlıklar üzerinden | Kaynak tarafı: paylar Toplam Kaynaklar üzerinden
A4: Kalem | B4: 2024 (Mn TL) | C4: 2025 (Mn TL) | D4: % Pay 2024 | E4: % Pay 2025 | F4: Δ pp | G4: % Değişim TL | H4: Yorum İpucu
A5: VARLIKLAR
A6: Dönen Varlıklar | B6: =Varlıklar!C20 -> 341910 | C6: =Varlıklar!D20 -> 436412 | D6: =IFERROR(B6/B$17,"") -> 0.24429018 | E6: =IFERROR(C6/C$17,"") -> 0.21856171 | F6: =IFERROR((C6/C$17)-(B6/B$17),"") -> -0.02572847 | G6: =IFERROR((C6-B6)/ABS(B6),"") -> 0.27639437 | H6: Likidite tampanı
A7: Nakit ve Nakit Benzerleri | B7: =Varlıklar!C7 -> 95992 | C7: =Varlıklar!D7 -> 86035 | D7: =IFERROR(B7/B$17,"") -> 0.068585016 | E7: =IFERROR(C7/C$17,"") -> 0.043087625 | F7: =IFERROR((C7/C$17)-(B7/B$17),"") -> -0.025497391 | G7: =IFERROR((C7-B7)/ABS(B7),"") -> -0.10372739 | H7: Hızlı erişilebilir nakit
A8: Finansal Yatırımlar (KV) | B8: =Varlıklar!C8 -> 118030 | C8: =Varlıklar!D8 -> 182732 | D8: =IFERROR(B8/B$17,"") -> 0.084330876 | E8: =IFERROR(C8/C$17,"") -> 0.091514941 | F8: =IFERROR((C8/C$17)-(B8/B$17),"") -> 0.0071840646 | G8: =IFERROR((C8-B8)/ABS(B8),"") -> 0.54818267 | H8: Likit yatırım
A9: Ticari Alacaklar (toplam) | B9: =Varlıklar!C10+Varlıklar!C11 -> 31908 | C9: =Varlıklar!D10+Varlıklar!D11 -> 45791 | D9: =IFERROR(B9/B$17,"") -> 0.022797845 | E9: =IFERROR(C9/C$17,"") -> 0.022932823 | F9: =IFERROR((C9/C$17)-(B9/B$17),"") -> 0.00013497863 | G9: =IFERROR((C9-B9)/ABS(B9),"") -> 0.43509465 | H9: Müşteri alacakları
A10: Stoklar | B10: =Varlıklar!C16 -> 23661 | C10: =Varlıklar!D16 -> 41472 | D10: =IFERROR(B10/B$17,"") -> 0.016905472 | E10: =IFERROR(C10/C$17,"") -> 0.020769803 | F10: =IFERROR((C10/C$17)-(B10/B$17),"") -> 0.0038643309 | G10: =IFERROR((C10-B10)/ABS(B10),"") -> 0.7527577 | H10: Yakıt + yedek parça
A11: Türev Araçlar (KV) | B11: =Varlıklar!C15 -> 4213 | C11: =Varlıklar!D15 -> 10583 | D11: =IFERROR(B11/B$17,"") -> 0.0030101329 | E11: =IFERROR(C11/C$17,"") -> 0.005300126 | F11: =IFERROR((C11/C$17)-(B11/B$17),"") -> 0.0022899931 | G11: =IFERROR((C11-B11)/ABS(B11),"") -> 1.5119867 | H11: Hedge pozisyonları
A12: Duran Varlıklar | B12: =Varlıklar!C36 -> 1057696 | C12: =Varlıklar!D36 -> 1560333 | D12: =IFERROR(B12/B$17,"") -> 0.75570982 | E12: =IFERROR(C12/C$17,"") -> 0.78143829 | F12: =IFERROR((C12/C$17)-(B12/B$17),"") -> 0.02572847 | G12: =IFERROR((C12-B12)/ABS(B12),"") -> 0.47521878 | H12: Uzun vadeli üretim varlıkları
A13: Maddi Duran Varlıklar | B13: =Varlıklar!C29 -> 248909 | C13: =Varlıklar!D29 -> 362618 | D13: =IFERROR(B13/B$17,"") -> 0.17784219 | E13: =IFERROR(C13/C$17,"") -> 0.18160456 | F13: =IFERROR((C13/C$17)-(B13/B$17),"") -> 0.0037623687 | G13: =IFERROR((C13-B13)/ABS(B13),"") -> 0.4568296 | H13: Sahip olunan filo
A14: Kullanım Hakkı Varlıkları | B14: =Varlıklar!C30 -> 621795 | C14: =Varlıklar!D30 -> 847758 | D14: =IFERROR(B14/B$17,"") -> 0.44426431 | E14: =IFERROR(C14/C$17,"") -> 0.42456999 | F14: =IFERROR((C14/C$17)-(B14/B$17),"") -> -0.019694327 | G14: =IFERROR((C14-B14)/ABS(B14),"") -> 0.36340434 | H14: Kiralanan filo (IFRS 16)
A15: Finansal Yatırımlar (UV) | B15: =Varlıklar!C23 -> 39253 | C15: =Varlıklar!D23 -> 114960 | D15: =IFERROR(B15/B$17,"") -> 0.02804575 | E15: =IFERROR(C15/C$17,"") -> 0.057573701 | F15: =IFERROR((C15/C$17)-(B15/B$17),"") -> 0.029527951 | G15: =IFERROR((C15-B15)/ABS(B15),"") -> 1.9286933 | H15: Stratejik yatırımlar
A16: Şerefiye + Diğer Maddi Olm. | B16: =Varlıklar!C32+Varlıklar!C33 -> 4886 | C16: =Varlıklar!D32+Varlıklar!D33 -> 8867 | D16: =IFERROR(B16/B$17,"") -> 0.0034909825 | E16: =IFERROR(C16/C$17,"") -> 0.0044407273 | F16: =IFERROR((C16/C$17)-(B16/B$17),"") -> 0.00094974482 | G16: =IFERROR((C16-B16)/ABS(B16),"") -> 0.81477691 | H16: Birleşme/marka değeri
A17: TOPLAM VARLIKLAR | B17: =Varlıklar!C38 -> 1399606 | C17: =Varlıklar!D38 -> 1996745 | D17: =IFERROR(B17/B$17,"") -> 1 | E17: =IFERROR(C17/C$17,"") -> 1 | F17: =IFERROR((C17/C$17)-(B17/B$17),"") -> 0 | G17: =IFERROR((C17-B17)/ABS(B17),"") -> 0.42664793 | H17: % 100 referans
A19: KAYNAKLAR
A20: Kısa Vadeli Yükümlülükler | B20: =Kaynaklar!C28 -> 339533 | C20: =Kaynaklar!D28 -> 442076 | D20: =IFERROR(B20/B$33,"") -> 0.24259184 | E20: =IFERROR(C20/C$33,"") -> 0.22139833 | F20: =IFERROR((C20/C$33)-(B20/B$33),"") -> -0.021193518 | G20: =IFERROR((C20-B20)/ABS(B20),"") -> 0.30201188 | H20: Bir yıl içinde ödenecek
A21: KV Banka Kredileri (top.) | B21: =Kaynaklar!C8+Kaynaklar!C10+Kaynaklar!C11 -> 65839 | C21: =Kaynaklar!D8+Kaynaklar!D10+Kaynaklar!D11 -> 76284 | D21: =IFERROR(B21/B$33,"") -> 0.047041096 | E21: =IFERROR(C21/C$33,"") -> 0.038204177 | F21: =IFERROR((C21/C$33)-(B21/B$33),"") -> -0.0088369186 | G21: =IFERROR((C21-B21)/ABS(B21),"") -> 0.15864457 | H21: 1 yıl içinde dönen finansman
A22: KV Kiralama Borçları | B22: =Kaynaklar!C12 -> 64571 | C22: =Kaynaklar!D12 -> 86152 | D22: =IFERROR(B22/B$33,"") -> 0.046135127 | E22: =IFERROR(C22/C$33,"") -> 0.04314622 | F22: =IFERROR((C22/C$33)-(B22/B$33),"") -> -0.0029889061 | G22: =IFERROR((C22-B22)/ABS(B22),"") -> 0.33422124 | H22: 1 yıl içindeki kira ödemeleri
A23: Ticari Borçlar (toplam) | B23: =Kaynaklar!C15+Kaynaklar!C16 -> 52792 | C23: =Kaynaklar!D15+Kaynaklar!D16 -> 78640 | D23: =IFERROR(B23/B$33,"") -> 0.037719187 | E23: =IFERROR(C23/C$33,"") -> 0.039384098 | F23: =IFERROR((C23/C$33)-(B23/B$33),"") -> 0.0016649109 | G23: =IFERROR((C23-B23)/ABS(B23),"") -> 0.48961964 | H23: Tedarikçi finansmanı
A24: Ertelenmiş Gelirler (KV) | B24: =Kaynaklar!C22 -> 104054 | C24: =Kaynaklar!D22 -> 151257 | D24: =IFERROR(B24/B$33,"") -> 0.074345209 | E24: =IFERROR(C24/C$33,"") -> 0.075751786 | F24: =IFERROR((C24/C$33)-(B24/B$33),"") -> 0.0014065775 | G24: =IFERROR((C24-B24)/ABS(B24),"") -> 0.45363946 | H24: Satılmış ama uçulmamış biletler
A25: Uzun Vadeli Yükümlülükler | B25: =Kaynaklar!C41 -> 380061 | C25: =Kaynaklar!D41 -> 643413 | D25: =IFERROR(B25/B$33,"") -> 0.27154856 | E25: =IFERROR(C25/C$33,"") -> 0.32223093 | F25: =IFERROR((C25/C$33)-(B25/B$33),"") -> 0.050682366 | G25: =IFERROR((C25-B25)/ABS(B25),"") -> 0.69292035 | H25: Yapısal kaldıraç
A26: UV Banka Kredileri | B26: =Kaynaklar!C32 -> 1176 | C26: =Kaynaklar!D32 -> 48993 | D26: =IFERROR(B26/B$33,"") -> 0.00084023647 | E26: =IFERROR(C26/C$33,"") -> 0.024536433 | F26: =IFERROR((C26/C$33)-(B26/B$33),"") -> 0.023696197 | G26: =IFERROR((C26-B26)/ABS(B26),"") -> 40.660714 | H26: Uzun vadeli kredi
A27: UV Kiralama Borçları | B27: =Kaynaklar!C33 -> 358353 | C27: =Kaynaklar!D33 -> 552824 | D27: =IFERROR(B27/B$33,"") -> 0.25603849 | E27: =IFERROR(C27/C$33,"") -> 0.27686259 | F27: =IFERROR((C27/C$33)-(B27/B$33),"") -> 0.020824109 | G27: =IFERROR((C27-B27)/ABS(B27),"") -> 0.54267998 | H27: Filonun kira yükü
A28: UV Çalışan Karşılıkları | B28: =Kaynaklar!C37 -> 8725 | C28: =Kaynaklar!D37 -> 12110 | D28: =IFERROR(B28/B$33,"") -> 0.0062338973 | E28: =IFERROR(C28/C$33,"") -> 0.0060648706 | F28: =IFERROR((C28/C$33)-(B28/B$33),"") -> -0.00016902668 | G28: =IFERROR((C28-B28)/ABS(B28),"") -> 0.38796562 | H28: Kıdem yükümlülükleri
A29: Özkaynaklar | B29: =Kaynaklar!C59 -> 680012 | C29: =Kaynaklar!D59 -> 911256 | D29: =IFERROR(B29/B$33,"") -> 0.48585959 | E29: =IFERROR(C29/C$33,"") -> 0.45637074 | F29: =IFERROR((C29/C$33)-(B29/B$33),"") -> -0.029488849 | G29: =IFERROR((C29-B29)/ABS(B29),"") -> 0.3400587 | H29: Hisse sahiplerinin payı
A30: Geçmiş Yıllar Karları | B30: =Kaynaklar!C55 -> 228888 | C30: =Kaynaklar!D55 -> 332426 | D30: =IFERROR(B30/B$33,"") -> 0.16353745 | E30: =IFERROR(C30/C$33,"") -> 0.16648395 | F30: =IFERROR((C30/C$33)-(B30/B$33),"") -> 0.0029464999 | G30: =IFERROR((C30-B30)/ABS(B30),"") -> 0.45235224 | H30: Birikmiş dağıtılmamış kâr
A31: Net Dönem Karı | B31: =Kaynaklar!C56 -> 113357 | C31: =Kaynaklar!D56 -> 118208 | D31: =IFERROR(B31/B$33,"") -> 0.080992079 | E31: =IFERROR(C31/C$33,"") -> 0.059200349 | F31: =IFERROR((C31/C$33)-(B31/B$33),"") -> -0.021791731 | G31: =IFERROR((C31-B31)/ABS(B31),"") -> 0.042794005 | H31: Yıllık kâr
A32: Yabancı Para Çevrim Farkları | B32: =Kaynaklar!C50 -> 281666 | C32: =Kaynaklar!D50 -> 428085 | D32: =IFERROR(B32/B$33,"") -> 0.20124664 | E32: =IFERROR(C32/C$33,"") -> 0.21439142 | F32: =IFERROR((C32/C$33)-(B32/B$33),"") -> 0.013144785 | G32: =IFERROR((C32-B32)/ABS(B32),"") -> 0.519832 | H32: TL değer kaybı etkisi
A33: TOPLAM KAYNAKLAR | B33: =Kaynaklar!C61 -> 1399606 | C33: =Kaynaklar!D61 -> 1996745 | D33: =IFERROR(B33/B$33,"") -> 1 | E33: =IFERROR(C33/C$33,"") -> 1 | F33: =IFERROR((C33/C$33)-(B33/B$33),"") -> 0 | G33: =IFERROR((C33-B33)/ABS(B33),"") -> 0.42664793 | H33: % 100 referans
A35: Renk Kodu: Yeşil = Diğer sayfaya bağlı | Siyah = Formül | Mavi (kaynak sayfalarda) = Bilançodan girilen sayı
A36: Δ pp = Yüzde puan değişimi (örn. %30,2'den %32,2'ye = +2,0 pp). Para birimi: Milyon TL.
A37: Bilançodaki sayıları 'Varlıklar' veya 'Kaynaklar' sayfasında değiştirirseniz, tüm yüzde paylar otomatik güncellenir.

Sheet 2021
A1: TMT A.O. — Konsolide Nakit Akış Tablosu (TL)
A2: 2021
A3: Tutarlar Milyon TL olarak gösterilmiştir (aksi belirtilmedikçe)
A5: Kalem | C5: 2021 | F5: % Değişim
A6: A. İŞLETME FAALİYETLERİNDEN NAKİT AKIŞLARI
A7: Net Dönem Kârı | C7: =+'[1]THY Konsolide Nakit Akış Tablos'!$C$4 -> 72306 | F7: =IFERROR((D7-C7)/ABS(C7),"") -> -1
A8: Amortisman ve İtfa Düzeltmesi | C8: 33999 | F8: =IFERROR((D8-C8)/ABS(C8),"") -> -1
A9: Çalışan Faydaları Karşılıkları | C9: =+'[1]THY Konsolide Nakit Akış Tablos'!$C$5 -> 3394 | F9: =IFERROR((D9-C9)/ABS(C9),"") -> -1
A10: Diğer Karşılıklar | C10: =+'[1]THY Konsolide Nakit Akış Tablos'!$C$6 -> 304 | F10: =IFERROR((D10-C10)/ABS(C10),"") -> -1
A11: =+'[1]THY Konsolide Nakit Akış Tablos'!$A$7 -> Muhtemel Riskler için Ayrılan Karşılıklar ile İlgili Düzeltmeler | C11: =+'[1]THY Konsolide Nakit Akış Tablos'!$C$7 -> -8
A12: Faiz Gelirleri (Düzeltme) | C12: =+'[1]THY Konsolide Nakit Akış Tablos'!$C$8 -> -53453 | F12: =IFERROR((D12-C12)/ABS(C12),"") -> 1
A13: Faiz Giderleri (Düzeltme) | C13: =+'[1]THY Konsolide Nakit Akış Tablos'!$C$9 -> 21107 | F13: =IFERROR((D13-C13)/ABS(C13),"") -> -1
A14: Yabancı Para Çevrim Farkları (Gerçekleşmemiş) | C14: =+'[1]THY Konsolide Nakit Akış Tablos'!$C$10 -> -15079 | F14: =IFERROR((D14-C14)/ABS(C14),"") -> 1
A15: Türev Araç Değer Düzeltmesi | C15: =+'[1]THY Konsolide Nakit Akış Tablos'!$C$11 -> 7612 | F15: =IFERROR((D15-C15)/ABS(C15),"") -> -1
A16: =+'[1]THY Konsolide Nakit Akış Tablos'!$A$12 -> Gerçeğe Uygun Değer Kayıpları ile İlgili Düzeltmeler | C16: =+'[1]THY Konsolide Nakit Akış Tablos'!$C$12 -> 2575
A17: =+'[1]THY Konsolide Nakit Akış Tablos'!$A$13 -> İştiraklerin Dağıtılmamış Karları İle İlgili Düzeltmeler | C17: =+'[1]THY Konsolide Nakit Akış Tablos'!$C$13 -> -5919
A18: Vergi Gideri Düzeltmesi | C18: =+'[1]THY Konsolide Nakit Akış Tablos'!$C$14 -> 8064 | F18: =IFERROR((D18-C18)/ABS(C18),"") -> -1
A19: Diğer Düzeltmeler (toplam) | C19: =+'[1]THY Konsolide Nakit Akış Tablos'!$C$15+'[1]THY Konsolide Nakit Akış Tablos'!$C$17+'[1]THY Konsolide Nakit Akış Tablos'!$C$16 -> -5242 | F19: =IFERROR((D19-C19)/ABS(C19),"") -> 1
A20: Ara Toplam (Düzeltmeler Sonrası) | C20: =SUM(C7:C19) -> 69660 | F20: =IFERROR((D20-C20)/ABS(C20),"") -> -1
A21: İşletme Sermayesi Değişimleri (net) | C21: =SUM('[1]THY Konsolide Nakit Akış Tablos'!$C$20:$C$32) -> 9319 | F21: =IFERROR((D21-C21)/ABS(C21),"") -> -1
A22: Ödemeler (Vergi + Çalışan Faydaları) | C22: =SUM('[1]THY Konsolide Nakit Akış Tablos'!$C$35:$C$36) -> -1863 | F22: =IFERROR((D22-C22)/ABS(C22),"") -> 1
A23: İşletme Faaliyetlerinden Net Nakit | C23: =SUM(C20:C22) -> 77116 | F23: =IFERROR((D23-C23)/ABS(C23),"") -> -1
A25: B. YATIRIM FAALİYETLERİNDEN NAKİT AKIŞLARI
A26: Maddi Duran Varlık Alımı (CapEx — brüt çıkış) | C26: =+'[1]THY Konsolide Nakit Akış Tablos'!$C$40 -> -43963 | F26: =IFERROR((D26-C26)/ABS(C26),"") -> 1
A27: Maddi Duran Varlık Satışı (giriş) | C27: =+'[1]THY Konsolide Nakit Akış Tablos'!$C$39 -> 464 | F27: =IFERROR((D27-C27)/ABS(C27),"") -> -1
A28: Diğer Yatırım Kalemleri (net) | F28: =IFERROR((D28-C28)/ABS(C28),"")
A29: Yatırım Faaliyetlerinden Net Nakit | C29: =SUM(C26:C28) -> -43499 | F29: =IFERROR((D29-C29)/ABS(C29),"") -> 1
A31: C. FİNANSMAN FAALİYETLERİNDEN NAKİT AKIŞLARI
A32: Yeni Krediler (giriş) | C32: =+'[1]THY Konsolide Nakit Akış Tablos'!$C$50 -> 90716 | F32: =IFERROR((D32-C32)/ABS(C32),"") -> -1
A33: Kredi Geri Ödemeleri (-) | C33: =+'[1]THY Konsolide Nakit Akış Tablos'!$C$51 -> -102308 | F33: =IFERROR((D33-C33)/ABS(C33),"") -> 1
A34: Kira Borç Ödemeleri (-) | C34: =+'[1]THY Konsolide Nakit Akış Tablos'!$C$52 -> -61522 | F34: =IFERROR((D34-C34)/ABS(C34),"") -> 1
A35: Temettü Ödemeleri (-) | F35: =IFERROR((D35-C35)/ABS(C35),"")
A36: Ödenen Faiz (-) | C36: =+'[1]THY Konsolide Nakit Akış Tablos'!$C$54 -> -12543 | F36: =IFERROR((D36-C36)/ABS(C36),"") -> 1
A37: Alınan Faiz (+) | C37: =+'[1]THY Konsolide Nakit Akış Tablos'!$C$55 -> 10495 | F37: =IFERROR((D37-C37)/ABS(C37),"") -> -1
A38: Diğer Finansman Kalemleri (net) | F38: =IFERROR((D38-C38)/ABS(C38),"")
A39: Finansman Faaliyetlerinde Kullanılan Net Nakit | C39: =SUM(C32:C38) -> -75162 | F39: =IFERROR((D39-C39)/ABS(C39),"") -> 1
A41: Yabancı Para Çevrim Etkisi | C41: =+'[1]THY Konsolide Nakit Akış Tablos'!$C$59 -> -20894 | F41: =IFERROR((D41-C41)/ABS(C41),"") -> 1
A42: Nakit ve Nakit Benzerlerindeki Net Değişim | F42: =IFERROR((D42-C42)/ABS(C42),"")
A43: Dönem Başı Nakit | C43: =+'[1]THY Konsolide Nakit Akış Tablos'!$C$61 -> 19941 | F43: =IFERROR((D43-C43)/ABS(C43),"") -> -1
A44: DÖNEM SONU NAKİT | C44: =+C43+C42 -> 19941 | F44: =IFERROR((D44-C44)/ABS(C44),"") -> -1
...
